Namespace(root='data/office31', data='Office31', source=['A'], target=['W'], train_resizing='res.', val_resizing='res.', resize_size=32, scale=[0.08, 1.0], ratio=[0.75, 1.3333333333333333], no_hflip=False, norm_mean=(0.485, 0.456, 0.406), norm_std=(0.229, 0.224, 0.225), arch='resnet18', bottleneck_dim=256, no_pool=False, scratch=False, trade_off=1.0, batch_size=32, lr=0.01, lr_gamma=0.001, lr_decay=0.75, momentum=0.9, weight_decay=0.001, workers=2, epochs=20, iters_per_epoch=1000, print_freq=100, seed=1, per_class_eval=False, log='logs/dann/Office31_A2W', phase='train', download_dataset_only='False', dataset_condensation='True', condensed_data_path='/home/daniel/exjobb/DatasetCondensation/result/res_DC_pre_processed_office31_ConvNet_1ipc.pt')
/home/daniel/exjobb/Transfer-Learning-Library/examples/domain_adaptation/image_classification/dann.py:56: UserWarning: You have chosen to seed training. This will turn on the CUDNN deterministic setting, which can slow down your training considerably! You may see unexpected behavior when restarting from checkpoints.
  warnings.warn('You have chosen to seed training. '
train_transform:  Compose(
    ResizeImage(size=(32, 32))
    RandomHorizontalFlip(p=0.5)
    ToTensor()
    Normalize(mean=(0.485, 0.456, 0.406), std=(0.229, 0.224, 0.225))
)
val_transform:  Compose(
    ResizeImage(size=(32, 32))
    ToTensor()
    Normalize(mean=(0.485, 0.456, 0.406), std=(0.229, 0.224, 0.225))
)
=> using model 'resnet18'
lr: 0.001
Traceback (most recent call last):
  File "/home/daniel/miniconda3/envs/transfer/lib/python3.9/site-packages/tllib-0.4-py3.9.egg/tllib/utils/data.py", line 50, in __next__
  File "/home/daniel/miniconda3/envs/transfer/lib/python3.9/site-packages/torch-1.7.1-py3.9-linux-x86_64.egg/torch/utils/data/dataloader.py", line 435, in __next__
    data = self._next_data()
  File "/home/daniel/miniconda3/envs/transfer/lib/python3.9/site-packages/torch-1.7.1-py3.9-linux-x86_64.egg/torch/utils/data/dataloader.py", line 1058, in _next_data
    raise StopIteration
StopIteration

During handling of the above exception, another exception occurred:

Traceback (most recent call last):
  File "/home/daniel/exjobb/Transfer-Learning-Library/examples/domain_adaptation/image_classification/dann.py", line 299, in <module>
    main(args)
  File "/home/daniel/exjobb/Transfer-Learning-Library/examples/domain_adaptation/image_classification/dann.py", line 146, in main
    train(train_source_iter, train_target_iter, classifier, domain_adv, optimizer,
  File "/home/daniel/exjobb/Transfer-Learning-Library/examples/domain_adaptation/image_classification/dann.py", line 187, in train
    x_s, labels_s = next(train_source_iter)[:2]
  File "/home/daniel/miniconda3/envs/transfer/lib/python3.9/site-packages/tllib-0.4-py3.9.egg/tllib/utils/data.py", line 55, in __next__
  File "/home/daniel/miniconda3/envs/transfer/lib/python3.9/site-packages/torch-1.7.1-py3.9-linux-x86_64.egg/torch/utils/data/dataloader.py", line 435, in __next__
    data = self._next_data()
  File "/home/daniel/miniconda3/envs/transfer/lib/python3.9/site-packages/torch-1.7.1-py3.9-linux-x86_64.egg/torch/utils/data/dataloader.py", line 1058, in _next_data
    raise StopIteration
StopIteration
