Namespace(root='data/digits', data='Digits', source=['MNIST'], target=['USPS'], train_resizing='res.', val_resizing='res.', resize_size=32, scale=[0.08, 1.0], ratio=[0.75, 1.3333333333333333], no_hflip=False, norm_mean=[0.485, 0.456], norm_std=[0.229, 0.224], arch='convnet', bottleneck_dim=256, no_pool=False, scratch=False, trade_off=1.0, batch_size=1, lr=0.01, lr_gamma=0.001, lr_decay=0.75, momentum=0.9, weight_decay=0.001, workers=2, epochs=20, iters_per_epoch=1000, print_freq=100, seed=None, per_class_eval=False, log='logs/dann/Digits_M2U', phase='train', download_dataset_only='False', dataset_condensation='True', condensed_data_path='/home/daniel/exjobb/DatasetCondensation/result/res_DC_pre_processed_mnist_ConvNet_1ipc.pt', no_aug='False', channel=3, convnet_weights_data_path='/home/daniel/exjobb/DatasetCondensation/result/state_dict_DC_pre_processed_mnist_ConvNet_1ipc.pt')
E
I
Traceback (most recent call last):
  File "/home/daniel/exjobb/Transfer-Learning-Library/examples/domain_adaptation/image_classification/dann.py", line 315, in <module>
    main(args)
  File "/home/daniel/exjobb/Transfer-Learning-Library/examples/domain_adaptation/image_classification/dann.py", line 69, in main
    val_transform = utils.get_val_transform(args.val_resizing, resize_size=args.resize_size,
TypeError: get_val_transform() got an unexpected keyword argument 'args'
